{"uuid": "c787a8b4-6e1c-41b9-9a9a-51fcdf655b73", "children": ["463702d5-2a64-41ec-bac5-68ea78ea6fcd"], "befores": [{"name": "driver", "status": "broken", "statusDetails": {"message": "selenium.common.exceptions.WebDriverException: Message: Service /root/.cache/selenium/chromedriver/linux64/133.0.6943.53/chromedriver unexpectedly exited. Status code was: 127\n\n", "trace": "  File \"/usr/local/lib/python3.9/site-packages/pluggy/_callers.py\", line 167, in _multicall\n    teardown.throw(outcome._exception)\n  File \"/usr/local/lib/python3.9/site-packages/_pytest/setuponly.py\", line 36, in pytest_fixture_setup\n    return (yield)\n  File \"/usr/local/lib/python3.9/site-packages/pluggy/_callers.py\", line 103, in _multicall\n    res = hook_impl.function(*args)\n  File \"/usr/local/lib/python3.9/site-packages/_pytest/fixtures.py\", line 1140, in pytest_fixture_setup\n    result = call_fixture_func(fixturefunc, request, kwargs)\n  File \"/usr/local/lib/python3.9/site-packages/_pytest/fixtures.py\", line 891, in call_fixture_func\n    fixture_result = next(generator)\n  File \"/app/test_aqa1/conftest.py\", line 14, in driver\n    driver = webdriver.Chrome(options=chrome_options)\n  File \"/usr/local/lib/python3.9/site-packages/selenium/webdriver/chrome/webdriver.py\", line 45, in __init__\n    super().__init__(\n  File \"/usr/local/lib/python3.9/site-packages/selenium/webdriver/chromium/webdriver.py\", line 55, in __init__\n    self.service.start()\n  File \"/usr/local/lib/python3.9/site-packages/selenium/webdriver/common/service.py\", line 113, in start\n    self.assert_process_still_running()\n  File \"/usr/local/lib/python3.9/site-packages/selenium/webdriver/common/service.py\", line 126, in assert_process_still_running\n    raise WebDriverException(f\"Service {self._path} unexpectedly exited. Status code was: {return_code}\")\n"}, "start": 1738763186382, "stop": 1738763186406}], "start": 1738763186382, "stop": 1738763186422}